[2025-08-27 22:24:48,775] ERROR in log: Internal Server Error: /admin/login/
Traceback (most recent call last):
  File "D:\api-project\venv\Lib\site-packages\django_redis\cache.py", line 29, in _decorator
    return method(self, *args, **kwargs)
  File "D:\api-project\venv\Lib\site-packages\django_redis\cache.py", line 138, in has_key
    return self.client.has_key(*args, **kwargs)
           ~~~~~~~~~~~~~~~~~~~^^^^^^^^^^^^^^^^^
  File "D:\api-project\venv\Lib\site-packages\django_redis\client\default.py", line 740, in has_key
    raise ConnectionInterrupted(connection=client) from e
django_redis.exceptions.ConnectionInterrupted: Redis ConnectionError: Error 10061 connecting to 127.0.0.1:6379. No connection could be made because the target machine actively refused it.

During handling of the above exception, another exception occurred:

Traceback (most recent call last):
  File "D:\api-project\venv\Lib\site-packages\django\core\handlers\exception.py", line 55, in inner
    response = get_response(request)
  File "D:\api-project\venv\Lib\site-packages\django\core\handlers\base.py", line 197, in _get_response
    response = wrapped_callback(request, *callback_args, **callback_kwargs)
  File "D:\api-project\venv\Lib\site-packages\django\utils\decorators.py", line 48, in _wrapper
    return bound_method(*args, **kwargs)
  File "D:\api-project\venv\Lib\site-packages\django\views\decorators\cache.py", line 80, in _view_wrapper
    response = view_func(request, *args, **kwargs)
  File "D:\api-project\venv\Lib\site-packages\django\contrib\admin\sites.py", line 449, in login
    return LoginView.as_view(**defaults)(request)
           ~~~~~~~~~~~~~~~~~~~~~~~~~~~~~^^^^^^^^^
  File "D:\api-project\venv\Lib\site-packages\django\views\generic\base.py", line 105, in view
    return self.dispatch(request, *args, **kwargs)
           ~~~~~~~~~~~~~^^^^^^^^^^^^^^^^^^^^^^^^^^
  File "D:\api-project\venv\Lib\site-packages\django\utils\decorators.py", line 48, in _wrapper
    return bound_method(*args, **kwargs)
  File "D:\api-project\venv\Lib\site-packages\django\utils\decorators.py", line 48, in _wrapper
    return bound_method(*args, **kwargs)
  File "D:\api-project\venv\Lib\site-packages\django\views\decorators\debug.py", line 143, in sensitive_post_parameters_wrapper
    return view(request, *args, **kwargs)
  File "D:\api-project\venv\Lib\site-packages\django\utils\decorators.py", line 48, in _wrapper
    return bound_method(*args, **kwargs)
  File "D:\api-project\venv\Lib\site-packages\django\utils\decorators.py", line 192, in _view_wrapper
    result = _process_exception(request, e)
  File "D:\api-project\venv\Lib\site-packages\django\utils\decorators.py", line 190, in _view_wrapper
    response = view_func(request, *args, **kwargs)
  File "D:\api-project\venv\Lib\site-packages\django\utils\decorators.py", line 48, in _wrapper
    return bound_method(*args, **kwargs)
  File "D:\api-project\venv\Lib\site-packages\django\views\decorators\cache.py", line 80, in _view_wrapper
    response = view_func(request, *args, **kwargs)
  File "D:\api-project\venv\Lib\site-packages\django\contrib\auth\views.py", line 89, in dispatch
    return super().dispatch(request, *args, **kwargs)
           ~~~~~~~~~~~~~~~~^^^^^^^^^^^^^^^^^^^^^^^^^^
  File "D:\api-project\venv\Lib\site-packages\django\views\generic\base.py", line 144, in dispatch
    return handler(request, *args, **kwargs)
  File "D:\api-project\venv\Lib\site-packages\django\views\generic\edit.py", line 151, in post
    return self.form_valid(form)
           ~~~~~~~~~~~~~~~^^^^^^
  File "D:\api-project\venv\Lib\site-packages\django\contrib\auth\views.py", line 108, in form_valid
    auth_login(self.request, form.get_user())
    ~~~~~~~~~~^^^^^^^^^^^^^^^^^^^^^^^^^^^^^^^
  File "D:\api-project\venv\Lib\site-packages\django\contrib\auth\__init__.py", line 187, in login
    request.session.cycle_key()
    ~~~~~~~~~~~~~~~~~~~~~~~~~^^
  File "D:\api-project\venv\Lib\site-packages\django\contrib\sessions\backends\base.py", line 432, in cycle_key
    self.create()
    ~~~~~~~~~~~^^
  File "D:\api-project\venv\Lib\site-packages\django\contrib\sessions\backends\cache.py", line 55, in create
    self._session_key = self._get_new_session_key()
                        ~~~~~~~~~~~~~~~~~~~~~~~~~^^
  File "D:\api-project\venv\Lib\site-packages\django\contrib\sessions\backends\base.py", line 196, in _get_new_session_key
    if not self.exists(session_key):
           ~~~~~~~~~~~^^^^^^^^^^^^^
  File "D:\api-project\venv\Lib\site-packages\django\contrib\sessions\backends\cache.py", line 117, in exists
    bool(session_key) and (self.cache_key_prefix + session_key) in self._cache
                          ^^^^^^^^^^^^^^^^^^^^^^^^^^^^^^^^^^^^^^^^^^^^^^^^^^^^
  File "D:\api-project\venv\Lib\site-packages\django\core\cache\backends\base.py", line 301, in __contains__
    return self.has_key(key)
           ~~~~~~~~~~~~^^^^^
  File "D:\api-project\venv\Lib\site-packages\django_redis\cache.py", line 36, in _decorator
    raise e.__cause__  # noqa: B904
    ^^^^^^^^^^^^^^^^^
  File "D:\api-project\venv\Lib\site-packages\django_redis\client\default.py", line 738, in has_key
    return client.exists(key) == 1
           ~~~~~~~~~~~~~^^^^^
  File "D:\api-project\venv\Lib\site-packages\redis\commands\core.py", line 1736, in exists
    return self.execute_command("EXISTS", *names, keys=names)
           ~~~~~~~~~~~~~~~~~~~~^^^^^^^^^^^^^^^^^^^^^^^^^^^^^^
  File "D:\api-project\venv\Lib\site-packages\redis\client.py", line 621, in execute_command
    return self._execute_command(*args, **options)
           ~~~~~~~~~~~~~~~~~~~~~^^^^^^^^^^^^^^^^^^
  File "D:\api-project\venv\Lib\site-packages\redis\client.py", line 627, in _execute_command
    conn = self.connection or pool.get_connection()
                              ~~~~~~~~~~~~~~~~~~~^^
  File "D:\api-project\venv\Lib\site-packages\redis\utils.py", line 195, in wrapper
    return func(*args, **kwargs)
  File "D:\api-project\venv\Lib\site-packages\redis\connection.py", line 1533, in get_connection
    connection.connect()
    ~~~~~~~~~~~~~~~~~~^^
  File "D:\api-project\venv\Lib\site-packages\redis\connection.py", line 380, in connect
    self.connect_check_health(check_health=True)
    ~~~~~~~~~~~~~~~~~~~~~~~~~^^^^^^^^^^^^^^^^^^^
  File "D:\api-project\venv\Lib\site-packages\redis\connection.py", line 397, in connect_check_health
    raise ConnectionError(self._error_message(e))
redis.exceptions.ConnectionError: Error 10061 connecting to 127.0.0.1:6379. No connection could be made because the target machine actively refused it.
[2025-08-27 22:24:48,775] ERROR in log: Internal Server Error: /admin/login/
Traceback (most recent call last):
  File "D:\api-project\venv\Lib\site-packages\django_redis\cache.py", line 29, in _decorator
    return method(self, *args, **kwargs)
  File "D:\api-project\venv\Lib\site-packages\django_redis\cache.py", line 138, in has_key
    return self.client.has_key(*args, **kwargs)
           ~~~~~~~~~~~~~~~~~~~^^^^^^^^^^^^^^^^^
  File "D:\api-project\venv\Lib\site-packages\django_redis\client\default.py", line 740, in has_key
    raise ConnectionInterrupted(connection=client) from e
django_redis.exceptions.ConnectionInterrupted: Redis ConnectionError: Error 10061 connecting to 127.0.0.1:6379. No connection could be made because the target machine actively refused it.

During handling of the above exception, another exception occurred:

Traceback (most recent call last):
  File "D:\api-project\venv\Lib\site-packages\django\core\handlers\exception.py", line 55, in inner
    response = get_response(request)
  File "D:\api-project\venv\Lib\site-packages\django\core\handlers\base.py", line 197, in _get_response
    response = wrapped_callback(request, *callback_args, **callback_kwargs)
  File "D:\api-project\venv\Lib\site-packages\django\utils\decorators.py", line 48, in _wrapper
    return bound_method(*args, **kwargs)
  File "D:\api-project\venv\Lib\site-packages\django\views\decorators\cache.py", line 80, in _view_wrapper
    response = view_func(request, *args, **kwargs)
  File "D:\api-project\venv\Lib\site-packages\django\contrib\admin\sites.py", line 449, in login
    return LoginView.as_view(**defaults)(request)
           ~~~~~~~~~~~~~~~~~~~~~~~~~~~~~^^^^^^^^^
  File "D:\api-project\venv\Lib\site-packages\django\views\generic\base.py", line 105, in view
    return self.dispatch(request, *args, **kwargs)
           ~~~~~~~~~~~~~^^^^^^^^^^^^^^^^^^^^^^^^^^
  File "D:\api-project\venv\Lib\site-packages\django\utils\decorators.py", line 48, in _wrapper
    return bound_method(*args, **kwargs)
  File "D:\api-project\venv\Lib\site-packages\django\utils\decorators.py", line 48, in _wrapper
    return bound_method(*args, **kwargs)
  File "D:\api-project\venv\Lib\site-packages\django\views\decorators\debug.py", line 143, in sensitive_post_parameters_wrapper
    return view(request, *args, **kwargs)
  File "D:\api-project\venv\Lib\site-packages\django\utils\decorators.py", line 48, in _wrapper
    return bound_method(*args, **kwargs)
  File "D:\api-project\venv\Lib\site-packages\django\utils\decorators.py", line 192, in _view_wrapper
    result = _process_exception(request, e)
  File "D:\api-project\venv\Lib\site-packages\django\utils\decorators.py", line 190, in _view_wrapper
    response = view_func(request, *args, **kwargs)
  File "D:\api-project\venv\Lib\site-packages\django\utils\decorators.py", line 48, in _wrapper
    return bound_method(*args, **kwargs)
  File "D:\api-project\venv\Lib\site-packages\django\views\decorators\cache.py", line 80, in _view_wrapper
    response = view_func(request, *args, **kwargs)
  File "D:\api-project\venv\Lib\site-packages\django\contrib\auth\views.py", line 89, in dispatch
    return super().dispatch(request, *args, **kwargs)
           ~~~~~~~~~~~~~~~~^^^^^^^^^^^^^^^^^^^^^^^^^^
  File "D:\api-project\venv\Lib\site-packages\django\views\generic\base.py", line 144, in dispatch
    return handler(request, *args, **kwargs)
  File "D:\api-project\venv\Lib\site-packages\django\views\generic\edit.py", line 151, in post
    return self.form_valid(form)
           ~~~~~~~~~~~~~~~^^^^^^
  File "D:\api-project\venv\Lib\site-packages\django\contrib\auth\views.py", line 108, in form_valid
    auth_login(self.request, form.get_user())
    ~~~~~~~~~~^^^^^^^^^^^^^^^^^^^^^^^^^^^^^^^
  File "D:\api-project\venv\Lib\site-packages\django\contrib\auth\__init__.py", line 187, in login
    request.session.cycle_key()
    ~~~~~~~~~~~~~~~~~~~~~~~~~^^
  File "D:\api-project\venv\Lib\site-packages\django\contrib\sessions\backends\base.py", line 432, in cycle_key
    self.create()
    ~~~~~~~~~~~^^
  File "D:\api-project\venv\Lib\site-packages\django\contrib\sessions\backends\cache.py", line 55, in create
    self._session_key = self._get_new_session_key()
                        ~~~~~~~~~~~~~~~~~~~~~~~~~^^
  File "D:\api-project\venv\Lib\site-packages\django\contrib\sessions\backends\base.py", line 196, in _get_new_session_key
    if not self.exists(session_key):
           ~~~~~~~~~~~^^^^^^^^^^^^^
  File "D:\api-project\venv\Lib\site-packages\django\contrib\sessions\backends\cache.py", line 117, in exists
    bool(session_key) and (self.cache_key_prefix + session_key) in self._cache
                          ^^^^^^^^^^^^^^^^^^^^^^^^^^^^^^^^^^^^^^^^^^^^^^^^^^^^
  File "D:\api-project\venv\Lib\site-packages\django\core\cache\backends\base.py", line 301, in __contains__
    return self.has_key(key)
           ~~~~~~~~~~~~^^^^^
  File "D:\api-project\venv\Lib\site-packages\django_redis\cache.py", line 36, in _decorator
    raise e.__cause__  # noqa: B904
    ^^^^^^^^^^^^^^^^^
  File "D:\api-project\venv\Lib\site-packages\django_redis\client\default.py", line 738, in has_key
    return client.exists(key) == 1
           ~~~~~~~~~~~~~^^^^^
  File "D:\api-project\venv\Lib\site-packages\redis\commands\core.py", line 1736, in exists
    return self.execute_command("EXISTS", *names, keys=names)
           ~~~~~~~~~~~~~~~~~~~~^^^^^^^^^^^^^^^^^^^^^^^^^^^^^^
  File "D:\api-project\venv\Lib\site-packages\redis\client.py", line 621, in execute_command
    return self._execute_command(*args, **options)
           ~~~~~~~~~~~~~~~~~~~~~^^^^^^^^^^^^^^^^^^
  File "D:\api-project\venv\Lib\site-packages\redis\client.py", line 627, in _execute_command
    conn = self.connection or pool.get_connection()
                              ~~~~~~~~~~~~~~~~~~~^^
  File "D:\api-project\venv\Lib\site-packages\redis\utils.py", line 195, in wrapper
    return func(*args, **kwargs)
  File "D:\api-project\venv\Lib\site-packages\redis\connection.py", line 1533, in get_connection
    connection.connect()
    ~~~~~~~~~~~~~~~~~~^^
  File "D:\api-project\venv\Lib\site-packages\redis\connection.py", line 380, in connect
    self.connect_check_health(check_health=True)
    ~~~~~~~~~~~~~~~~~~~~~~~~~^^^^^^^^^^^^^^^^^^^
  File "D:\api-project\venv\Lib\site-packages\redis\connection.py", line 397, in connect_check_health
    raise ConnectionError(self._error_message(e))
redis.exceptions.ConnectionError: Error 10061 connecting to 127.0.0.1:6379. No connection could be made because the target machine actively refused it.
[2025-08-27 22:24:48,794] ERROR in basehttp: "POST /admin/login/?next=/admin/ HTTP/1.1" 500 224602
[2025-08-27 22:24:48,794] ERROR in basehttp: "POST /admin/login/?next=/admin/ HTTP/1.1" 500 224602
[2025-08-27 23:20:55,460] ERROR in exceptions: [TokenObtainPairView] MethodNotAllowed: {'detail': ErrorDetail(string='Method "GET" not allowed.', code='method_not_allowed')}
[2025-08-27 23:25:39,178] ERROR in exceptions: [TokenRefreshView] MethodNotAllowed: {'detail': ErrorDetail(string='Method "GET" not allowed.', code='method_not_allowed')}
[2025-08-27 23:25:42,000] ERROR in exceptions: [TokenRefreshView] ValidationError: {'refresh': [ErrorDetail(string='This field may not be blank.', code='blank')]}
[2025-08-27 23:26:15,369] ERROR in exceptions: [TokenBlacklistView] MethodNotAllowed: {'detail': ErrorDetail(string='Method "GET" not allowed.', code='method_not_allowed')}
[2025-08-27 23:26:26,107] ERROR in exceptions: [TokenBlacklistView] ValidationError: {'refresh': [ErrorDetail(string='This field may not be blank.', code='blank')]}
[2025-08-27 23:26:52,678] ERROR in exceptions: [TokenObtainPairView] MethodNotAllowed: {'detail': ErrorDetail(string='Method "GET" not allowed.', code='method_not_allowed')}
[2025-08-27 23:27:16,102] ERROR in exceptions: [APIRootView] NotAuthenticated: {'detail': ErrorDetail(string='Authentication credentials were not provided.', code='not_authenticated')}
[2025-08-27 23:27:52,019] ERROR in exceptions: [TokenObtainPairView] MethodNotAllowed: {'detail': ErrorDetail(string='Method "GET" not allowed.', code='method_not_allowed')}
[2025-08-27 23:28:03,995] ERROR in exceptions: [TokenObtainPairView] ValidationError: {'username': [ErrorDetail(string='This field is required.', code='required')], 'password': [ErrorDetail(string='This field is required.', code='required')]}
[2025-08-27 23:28:40,389] ERROR in exceptions: [APIRootView] NotAuthenticated: {'detail': ErrorDetail(string='Authentication credentials were not provided.', code='not_authenticated')}
[2025-08-27 23:29:36,981] ERROR in exceptions: [APIRootView] NotAuthenticated: {'detail': ErrorDetail(string='Authentication credentials were not provided.', code='not_authenticated')}
[2025-08-27 23:29:46,001] ERROR in exceptions: [APIRootView] NotAuthenticated: {'detail': ErrorDetail(string='Authentication credentials were not provided.', code='not_authenticated')}
[2025-08-27 23:37:52,949] ERROR in exceptions: [APIRootView] NotAuthenticated: {'detail': ErrorDetail(string='Authentication credentials were not provided.', code='not_authenticated')}
[2025-08-28 22:12:46,393] ERROR in exceptions: [APIRootView] NotAuthenticated: {'detail': ErrorDetail(string='Authentication credentials were not provided.', code='not_authenticated')}
[2025-08-29 01:52:15,947] ERROR in exceptions: [APIRootView] NotAuthenticated: {'detail': ErrorDetail(string='Authentication credentials were not provided.', code='not_authenticated')}
[2025-08-29 01:52:31,151] ERROR in exceptions: [APIRootView] NotAuthenticated: {'detail': ErrorDetail(string='Authentication credentials were not provided.', code='not_authenticated')}
[2025-08-29 01:55:40,593] ERROR in exceptions: [APIRootView] NotAuthenticated: {'detail': ErrorDetail(string='Authentication credentials were not provided.', code='not_authenticated')}
[2025-08-29 01:55:50,698] ERROR in exceptions: [APIRootView] NotAuthenticated: {'detail': ErrorDetail(string='Authentication credentials were not provided.', code='not_authenticated')}
[2025-08-29 02:40:49,709] ERROR in exceptions: [TokenObtainPairView] MethodNotAllowed: {'detail': ErrorDetail(string='Method "GET" not allowed.', code='method_not_allowed')}
[2025-08-29 03:27:01,102] ERROR in exceptions: [TokenObtainPairView] MethodNotAllowed: {'detail': ErrorDetail(string='Method "GET" not allowed.', code='method_not_allowed')}
[2025-08-29 03:27:21,240] ERROR in exceptions: [RegisterView] MethodNotAllowed: {'detail': ErrorDetail(string='Method "GET" not allowed.', code='method_not_allowed')}
[2025-08-29 14:44:27,147] ERROR in exceptions: [APIRootView] NotAuthenticated: {'detail': ErrorDetail(string='Authentication credentials were not provided.', code='not_authenticated')}
[2025-08-29 14:50:16,994] ERROR in log: Internal Server Error: /accounts/login/
Traceback (most recent call last):
  File "D:\api-project\venv\Lib\site-packages\django\core\handlers\exception.py", line 55, in inner
    response = get_response(request)
  File "D:\api-project\venv\Lib\site-packages\django\core\handlers\base.py", line 220, in _get_response
    response = response.render()
  File "D:\api-project\venv\Lib\site-packages\django\template\response.py", line 114, in render
    self.content = self.rendered_content
                   ^^^^^^^^^^^^^^^^^^^^^
  File "D:\api-project\venv\Lib\site-packages\django\template\response.py", line 90, in rendered_content
    template = self.resolve_template(self.template_name)
  File "D:\api-project\venv\Lib\site-packages\django\template\response.py", line 72, in resolve_template
    return select_template(template, using=self.using)
  File "D:\api-project\venv\Lib\site-packages\django\template\loader.py", line 47, in select_template
    raise TemplateDoesNotExist(", ".join(template_name_list), chain=chain)
django.template.exceptions.TemplateDoesNotExist: registration/login.html
[2025-08-29 14:50:16,994] ERROR in log: Internal Server Error: /accounts/login/
Traceback (most recent call last):
  File "D:\api-project\venv\Lib\site-packages\django\core\handlers\exception.py", line 55, in inner
    response = get_response(request)
  File "D:\api-project\venv\Lib\site-packages\django\core\handlers\base.py", line 220, in _get_response
    response = response.render()
  File "D:\api-project\venv\Lib\site-packages\django\template\response.py", line 114, in render
    self.content = self.rendered_content
                   ^^^^^^^^^^^^^^^^^^^^^
  File "D:\api-project\venv\Lib\site-packages\django\template\response.py", line 90, in rendered_content
    template = self.resolve_template(self.template_name)
  File "D:\api-project\venv\Lib\site-packages\django\template\response.py", line 72, in resolve_template
    return select_template(template, using=self.using)
  File "D:\api-project\venv\Lib\site-packages\django\template\loader.py", line 47, in select_template
    raise TemplateDoesNotExist(", ".join(template_name_list), chain=chain)
django.template.exceptions.TemplateDoesNotExist: registration/login.html
[2025-08-29 14:50:16,999] ERROR in basehttp: "GET /accounts/login/?next=/admin/ HTTP/1.1" 500 86882
[2025-08-29 14:50:16,999] ERROR in basehttp: "GET /accounts/login/?next=/admin/ HTTP/1.1" 500 86882
[2025-08-29 16:21:18,043] ERROR in exceptions: [RegisterView] MethodNotAllowed: {'detail': ErrorDetail(string='Method "GET" not allowed.', code='method_not_allowed')}
[2025-08-29 16:21:35,098] ERROR in exceptions: [TokenObtainPairView] MethodNotAllowed: {'detail': ErrorDetail(string='Method "GET" not allowed.', code='method_not_allowed')}
[2025-08-29 16:22:19,686] ERROR in exceptions: [TokenObtainPairView] MethodNotAllowed: {'detail': ErrorDetail(string='Method "GET" not allowed.', code='method_not_allowed')}
[2025-08-29 16:22:40,768] ERROR in exceptions: [APIRootView] NotAuthenticated: {'detail': ErrorDetail(string='Authentication credentials were not provided.', code='not_authenticated')}
[2025-08-29 16:22:53,980] ERROR in exceptions: [APIRootView] NotAuthenticated: {'detail': ErrorDetail(string='Authentication credentials were not provided.', code='not_authenticated')}
[2025-08-29 16:26:02,993] ERROR in exceptions: [APIRootView] NotAuthenticated: {'detail': ErrorDetail(string='Authentication credentials were not provided.', code='not_authenticated')}
[2025-08-29 16:26:18,880] ERROR in exceptions: [APIRootView] NotAuthenticated: {'detail': ErrorDetail(string='Authentication credentials were not provided.', code='not_authenticated')}
[2025-08-29 16:28:04,094] ERROR in exceptions: [RegisterView] MethodNotAllowed: {'detail': ErrorDetail(string='Method "GET" not allowed.', code='method_not_allowed')}
[2025-08-29 16:28:40,804] ERROR in exceptions: [TokenObtainPairView] MethodNotAllowed: {'detail': ErrorDetail(string='Method "GET" not allowed.', code='method_not_allowed')}
[2025-08-29 16:29:16,413] ERROR in exceptions: [TokenRefreshView] MethodNotAllowed: {'detail': ErrorDetail(string='Method "GET" not allowed.', code='method_not_allowed')}
[2025-08-29 16:29:35,631] ERROR in exceptions: [TokenBlacklistView] MethodNotAllowed: {'detail': ErrorDetail(string='Method "GET" not allowed.', code='method_not_allowed')}
[2025-08-29 16:29:52,174] ERROR in exceptions: [LogoutView] NotAuthenticated: {'detail': ErrorDetail(string='Authentication credentials were not provided.', code='not_authenticated')}
[2025-08-29 16:30:09,343] ERROR in exceptions: [APIRootView] NotAuthenticated: {'detail': ErrorDetail(string='Authentication credentials were not provided.', code='not_authenticated')}
[2025-08-29 16:30:50,612] ERROR in exceptions: [APIRootView] NotAuthenticated: {'detail': ErrorDetail(string='Authentication credentials were not provided.', code='not_authenticated')}
[2025-08-29 16:31:16,990] ERROR in exceptions: [APIRootView] NotAuthenticated: {'detail': ErrorDetail(string='Authentication credentials were not provided.', code='not_authenticated')}
[2025-08-29 16:31:45,027] ERROR in exceptions: [APIRootView] NotAuthenticated: {'detail': ErrorDetail(string='Authentication credentials were not provided.', code='not_authenticated')}
[2025-08-29 16:31:56,798] ERROR in exceptions: [APIRootView] NotAuthenticated: {'detail': ErrorDetail(string='Authentication credentials were not provided.', code='not_authenticated')}
[2025-08-29 16:32:10,016] ERROR in exceptions: [APIRootView] NotAuthenticated: {'detail': ErrorDetail(string='Authentication credentials were not provided.', code='not_authenticated')}
[2025-08-29 16:32:20,617] ERROR in exceptions: [APIRootView] NotAuthenticated: {'detail': ErrorDetail(string='Authentication credentials were not provided.', code='not_authenticated')}
[2025-08-29 16:32:36,073] ERROR in exceptions: [APIRootView] NotAuthenticated: {'detail': ErrorDetail(string='Authentication credentials were not provided.', code='not_authenticated')}
[2025-08-29 16:38:05,033] ERROR in exceptions: [APIRootView] NotAuthenticated: {'detail': ErrorDetail(string='Authentication credentials were not provided.', code='not_authenticated')}
[2025-08-29 16:38:15,335] ERROR in exceptions: [APIRootView] NotAuthenticated: {'detail': ErrorDetail(string='Authentication credentials were not provided.', code='not_authenticated')}
[2025-08-29 16:38:29,365] ERROR in exceptions: [APIRootView] NotAuthenticated: {'detail': ErrorDetail(string='Authentication credentials were not provided.', code='not_authenticated')}
[2025-08-29 16:38:40,968] ERROR in exceptions: [APIRootView] NotAuthenticated: {'detail': ErrorDetail(string='Authentication credentials were not provided.', code='not_authenticated')}
[2025-08-29 16:38:50,527] ERROR in exceptions: [APIRootView] NotAuthenticated: {'detail': ErrorDetail(string='Authentication credentials were not provided.', code='not_authenticated')}
[2025-08-29 16:39:04,082] ERROR in exceptions: [APIRootView] NotAuthenticated: {'detail': ErrorDetail(string='Authentication credentials were not provided.', code='not_authenticated')}
[2025-08-29 16:40:46,520] ERROR in exceptions: [APIRootView] NotAuthenticated: {'detail': ErrorDetail(string='Authentication credentials were not provided.', code='not_authenticated')}
[2025-08-29 16:40:57,231] ERROR in exceptions: [APIRootView] NotAuthenticated: {'detail': ErrorDetail(string='Authentication credentials were not provided.', code='not_authenticated')}
[2025-08-29 16:41:53,792] ERROR in exceptions: [LogoutView] NotAuthenticated: {'detail': ErrorDetail(string='Authentication credentials were not provided.', code='not_authenticated')}
[2025-08-29 17:32:21,948] ERROR in exceptions: [APIRootView] NotAuthenticated: {'detail': ErrorDetail(string='Authentication credentials were not provided.', code='not_authenticated')}
[2025-08-29 18:07:42,388] ERROR in log: Internal Server Error: /accounts/login/
Traceback (most recent call last):
  File "D:\api-project\venv\Lib\site-packages\django\core\handlers\exception.py", line 55, in inner
    response = get_response(request)
  File "D:\api-project\venv\Lib\site-packages\django\core\handlers\base.py", line 220, in _get_response
    response = response.render()
  File "D:\api-project\venv\Lib\site-packages\django\template\response.py", line 114, in render
    self.content = self.rendered_content
                   ^^^^^^^^^^^^^^^^^^^^^
  File "D:\api-project\venv\Lib\site-packages\django\template\response.py", line 90, in rendered_content
    template = self.resolve_template(self.template_name)
  File "D:\api-project\venv\Lib\site-packages\django\template\response.py", line 72, in resolve_template
    return select_template(template, using=self.using)
  File "D:\api-project\venv\Lib\site-packages\django\template\loader.py", line 47, in select_template
    raise TemplateDoesNotExist(", ".join(template_name_list), chain=chain)
django.template.exceptions.TemplateDoesNotExist: registration/login.html
[2025-08-29 18:07:42,388] ERROR in log: Internal Server Error: /accounts/login/
Traceback (most recent call last):
  File "D:\api-project\venv\Lib\site-packages\django\core\handlers\exception.py", line 55, in inner
    response = get_response(request)
  File "D:\api-project\venv\Lib\site-packages\django\core\handlers\base.py", line 220, in _get_response
    response = response.render()
  File "D:\api-project\venv\Lib\site-packages\django\template\response.py", line 114, in render
    self.content = self.rendered_content
                   ^^^^^^^^^^^^^^^^^^^^^
  File "D:\api-project\venv\Lib\site-packages\django\template\response.py", line 90, in rendered_content
    template = self.resolve_template(self.template_name)
  File "D:\api-project\venv\Lib\site-packages\django\template\response.py", line 72, in resolve_template
    return select_template(template, using=self.using)
  File "D:\api-project\venv\Lib\site-packages\django\template\loader.py", line 47, in select_template
    raise TemplateDoesNotExist(", ".join(template_name_list), chain=chain)
django.template.exceptions.TemplateDoesNotExist: registration/login.html
[2025-08-29 18:07:42,393] ERROR in basehttp: "GET /accounts/login/?next=/admin/ HTTP/1.1" 500 87018
[2025-08-29 18:07:42,393] ERROR in basehttp: "GET /accounts/login/?next=/admin/ HTTP/1.1" 500 87018
[2025-08-29 18:23:59,783] ERROR in exceptions: [APIRootView] NotAuthenticated: {'detail': ErrorDetail(string='Authentication credentials were not provided.', code='not_authenticated')}
[2025-08-29 18:24:09,766] ERROR in exceptions: [RegisterView] MethodNotAllowed: {'detail': ErrorDetail(string='Method "GET" not allowed.', code='method_not_allowed')}
[2025-08-29 22:02:23,209] ERROR in exceptions: [TokenObtainPairView] MethodNotAllowed: {'detail': ErrorDetail(string='Method "GET" not allowed.', code='method_not_allowed')}
[2025-08-29 22:05:30,969] ERROR in exceptions: [TokenObtainPairView] MethodNotAllowed: {'detail': ErrorDetail(string='Method "GET" not allowed.', code='method_not_allowed')}
[2025-08-29 22:06:03,407] ERROR in exceptions: [TokenObtainPairView] MethodNotAllowed: {'detail': ErrorDetail(string='Method "GET" not allowed.', code='method_not_allowed')}
[2025-08-29 22:06:42,638] ERROR in exceptions: [TokenObtainPairView] MethodNotAllowed: {'detail': ErrorDetail(string='Method "GET" not allowed.', code='method_not_allowed')}
[2025-08-29 22:06:52,955] ERROR in exceptions: [TokenObtainPairView] MethodNotAllowed: {'detail': ErrorDetail(string='Method "GET" not allowed.', code='method_not_allowed')}
[2025-08-29 22:07:32,164] ERROR in exceptions: [TokenObtainPairView] ValidationError: {'username': [ErrorDetail(string='This field is required.', code='required')], 'password': [ErrorDetail(string='This field is required.', code='required')]}
[2025-08-29 22:08:24,859] ERROR in exceptions: [TokenObtainPairView] ValidationError: {'username': [ErrorDetail(string='This field is required.', code='required')], 'password': [ErrorDetail(string='This field is required.', code='required')]}
[2025-08-29 22:09:03,681] ERROR in log: Internal Server Error: /admin
Traceback (most recent call last):
  File "D:\api-project\venv\Lib\site-packages\django\core\handlers\exception.py", line 55, in inner
    response = get_response(request)
  File "D:\api-project\venv\Lib\site-packages\django\utils\deprecation.py", line 122, in __call__
    response = self.process_response(request, response)
  File "D:\api-project\venv\Lib\site-packages\django\middleware\common.py", line 108, in process_response
    return self.response_redirect_class(self.get_full_path_with_slash(request))
                                        ~~~~~~~~~~~~~~~~~~~~~~~~~~~~~^^^^^^^^^
  File "D:\api-project\venv\Lib\site-packages\django\middleware\common.py", line 87, in get_full_path_with_slash
    raise RuntimeError(
    ...<9 lines>...
    )
RuntimeError: You called this URL via POST, but the URL doesn't end in a slash and you have APPEND_SLASH set. Django can't redirect to the slash URL while maintaining POST data. Change your form to point to 127.0.0.1:8000/admin/ (note the trailing slash), or set APPEND_SLASH=False in your Django settings.
[2025-08-29 22:09:03,681] ERROR in log: Internal Server Error: /admin
Traceback (most recent call last):
  File "D:\api-project\venv\Lib\site-packages\django\core\handlers\exception.py", line 55, in inner
    response = get_response(request)
  File "D:\api-project\venv\Lib\site-packages\django\utils\deprecation.py", line 122, in __call__
    response = self.process_response(request, response)
  File "D:\api-project\venv\Lib\site-packages\django\middleware\common.py", line 108, in process_response
    return self.response_redirect_class(self.get_full_path_with_slash(request))
                                        ~~~~~~~~~~~~~~~~~~~~~~~~~~~~~^^^^^^^^^
  File "D:\api-project\venv\Lib\site-packages\django\middleware\common.py", line 87, in get_full_path_with_slash
    raise RuntimeError(
    ...<9 lines>...
    )
RuntimeError: You called this URL via POST, but the URL doesn't end in a slash and you have APPEND_SLASH set. Django can't redirect to the slash URL while maintaining POST data. Change your form to point to 127.0.0.1:8000/admin/ (note the trailing slash), or set APPEND_SLASH=False in your Django settings.
[2025-08-29 22:09:03,686] ERROR in basehttp: "POST /admin HTTP/1.1" 500 74290
[2025-08-29 22:09:03,686] ERROR in basehttp: "POST /admin HTTP/1.1" 500 74290
[2025-08-29 22:36:09,932] ERROR in exceptions: [TokenObtainPairView] MethodNotAllowed: {'detail': ErrorDetail(string='Method "GET" not allowed.', code='method_not_allowed')}
